void function(int i) throw(std::exception, CustomExceptionType)
{
	do_something(i);
}
